INFO:root:Extract 225 images
ERROR:root:Traceback (most recent call last):
  File "/app/extraction/__init__.py", line 159, in extract
    self.save_text(df_text, num_page)
  File "/app/extraction/__init__.py", line 125, in save_text
    self.write_text(f, df_left.sort_values('top'), 'lines_combine')
  File "/app/extraction/__init__.py", line 110, in write_text
    text = self.process_text(text)
TypeError: process_text() takes 1 positional argument but 2 were given

INFO:root:Fail to extract page 12
ERROR:root:Traceback (most recent call last):
  File "/app/extraction/__init__.py", line 159, in extract
    self.save_text(df_text, num_page)
  File "/app/extraction/__init__.py", line 125, in save_text
    self.write_text(f, df_left.sort_values('top'), 'lines_combine')
  File "/app/extraction/__init__.py", line 110, in write_text
    text = self.process_text(text)
TypeError: process_text() takes 1 positional argument but 2 were given

INFO:root:Fail to extract page 13
INFO:root:Extract 225 images
ERROR:root:Traceback (most recent call last):
  File "/app/extraction/__init__.py", line 159, in extract
    self.save_text(df_text, num_page)
  File "/app/extraction/__init__.py", line 125, in save_text
    self.write_text(f, df_left.sort_values('top'), 'lines_combine')
  File "/app/extraction/__init__.py", line 111, in write_text
    if not self.isTitle(text) :
  File "/app/extraction/__init__.py", line 98, in isTitle
    n_sentence = len(sent_tokenize(text))
  File "/usr/local/lib/python3.7/site-packages/nltk/tokenize/__init__.py", line 107, in sent_tokenize
    tokenizer = load("tokenizers/punkt/{0}.pickle".format(language))
  File "/usr/local/lib/python3.7/site-packages/nltk/data.py", line 750, in load
    opened_resource = _open(resource_url)
  File "/usr/local/lib/python3.7/site-packages/nltk/data.py", line 875, in _open
    return find(path_, path + [""]).open()
  File "/usr/local/lib/python3.7/site-packages/nltk/data.py", line 583, in find
    raise LookupError(resource_not_found)
LookupError: 
**********************************************************************
  Resource [93mpunkt[0m not found.
  Please use the NLTK Downloader to obtain the resource:

  [31m>>> import nltk
  >>> nltk.download('punkt')
  [0m
  For more information see: https://www.nltk.org/data.html

  Attempted to load [93mtokenizers/punkt/PY3/english.pickle[0m

  Searched in:
    - '/root/nltk_data'
    - '/usr/local/nltk_data'
    - '/usr/local/share/nltk_data'
    - '/usr/local/lib/nltk_data'
    - '/usr/share/nltk_data'
    - '/usr/local/share/nltk_data'
    - '/usr/lib/nltk_data'
    - '/usr/local/lib/nltk_data'
    - ''
**********************************************************************


INFO:root:Fail to extract page 12
ERROR:root:Traceback (most recent call last):
  File "/app/extraction/__init__.py", line 159, in extract
    self.save_text(df_text, num_page)
  File "/app/extraction/__init__.py", line 125, in save_text
    self.write_text(f, df_left.sort_values('top'), 'lines_combine')
  File "/app/extraction/__init__.py", line 111, in write_text
    if not self.isTitle(text) :
  File "/app/extraction/__init__.py", line 98, in isTitle
    n_sentence = len(sent_tokenize(text))
  File "/usr/local/lib/python3.7/site-packages/nltk/tokenize/__init__.py", line 107, in sent_tokenize
    tokenizer = load("tokenizers/punkt/{0}.pickle".format(language))
  File "/usr/local/lib/python3.7/site-packages/nltk/data.py", line 750, in load
    opened_resource = _open(resource_url)
  File "/usr/local/lib/python3.7/site-packages/nltk/data.py", line 875, in _open
    return find(path_, path + [""]).open()
  File "/usr/local/lib/python3.7/site-packages/nltk/data.py", line 583, in find
    raise LookupError(resource_not_found)
LookupError: 
**********************************************************************
  Resource [93mpunkt[0m not found.
  Please use the NLTK Downloader to obtain the resource:

  [31m>>> import nltk
  >>> nltk.download('punkt')
  [0m
  For more information see: https://www.nltk.org/data.html

  Attempted to load [93mtokenizers/punkt/PY3/english.pickle[0m

  Searched in:
    - '/root/nltk_data'
    - '/usr/local/nltk_data'
    - '/usr/local/share/nltk_data'
    - '/usr/local/lib/nltk_data'
    - '/usr/share/nltk_data'
    - '/usr/local/share/nltk_data'
    - '/usr/lib/nltk_data'
    - '/usr/local/lib/nltk_data'
    - ''
**********************************************************************


INFO:root:Fail to extract page 13
INFO:root:Extract 225 images
INFO:root:Successfully extract page 12
INFO:root:Successfully extract page 13
INFO:root:Extract 225 images
INFO:root:Successfully extract page 12
INFO:root:Successfully extract page 13
ERROR:root:Traceback (most recent call last):
  File "/app/extraction/__init__.py", line 139, in combine_text
    with open(filename) as infile:
FileNotFoundError: [Errno 2] No such file or directory: '/app/extracted_data/14/page_14.txt'

ERROR:root:[Errno 2] No such file or directory: '/app/extracted_data/14/page_14.txt'
ERROR:root:Traceback (most recent call last):
  File "/app/extraction/__init__.py", line 139, in combine_text
    with open(filename) as infile:
FileNotFoundError: [Errno 2] No such file or directory: '/app/extracted_data/14/page_14.txt'

ERROR:root:[Errno 2] No such file or directory: '/app/extracted_data/14/page_14.txt'
ERROR:root:Traceback (most recent call last):
  File "/app/extraction/__init__.py", line 139, in combine_text
    with open(filename) as infile:
FileNotFoundError: [Errno 2] No such file or directory: '/app/extracted_data/13/page_13.txt'

ERROR:root:[Errno 2] No such file or directory: '/app/extracted_data/13/page_13.txt'
ERROR:root:Traceback (most recent call last):
  File "/app/extraction/__init__.py", line 139, in combine_text
    with open(filename) as infile:
FileNotFoundError: [Errno 2] No such file or directory: '/app/extracted_data/14/page_14.txt'

ERROR:root:[Errno 2] No such file or directory: '/app/extracted_data/14/page_14.txt'
ERROR:root:Traceback (most recent call last):
  File "/app/extraction/__init__.py", line 139, in combine_text
    with open(filename) as infile:
FileNotFoundError: [Errno 2] No such file or directory: '/app/extracted_data/12/page_12.txt'

ERROR:root:[Errno 2] No such file or directory: '/app/extracted_data/12/page_12.txt'
ERROR:root:Traceback (most recent call last):
  File "/app/extraction/__init__.py", line 139, in combine_text
    with open(filename) as infile:
FileNotFoundError: [Errno 2] No such file or directory: '/app/extracted_data/13/page_13.txt'

ERROR:root:[Errno 2] No such file or directory: '/app/extracted_data/13/page_13.txt'
ERROR:root:Traceback (most recent call last):
  File "/app/extraction/__init__.py", line 139, in combine_text
    with open(filename) as infile:
FileNotFoundError: [Errno 2] No such file or directory: '/app/extracted_data/14/page_14.txt'

ERROR:root:[Errno 2] No such file or directory: '/app/extracted_data/14/page_14.txt'
INFO:root:Extract 225 images
INFO:root:Successfully extract page 12
INFO:root:Successfully extract page 13
INFO:root:Successfully extract page 14
INFO:root:Extract 225 images
INFO:root:Successfully extract page 12
INFO:root:Successfully extract page 13
INFO:root:Successfully extract page 14
INFO:werkzeug: * Running on http://127.0.0.1:5000/ (Press CTRL+C to quit)
